    return await self._do_post(
           ^^^^^^^^^^^^^^^^^^^^
  File "/opt/render/project/src/.venv/lib/python3.11/site-packages/telegram/ext/_extbot.py", line 369, in _do_post
    return await super()._do_post(
           ^^^^^^^^^^^^^^^^^^^^^^^
  File "/opt/render/project/src/.venv/lib/python3.11/site-packages/telegram/_bot.py", line 726, in _do_post
    result = await request.post(
             ^^^^^^^^^^^^^^^^^^^
  File "/opt/render/project/src/.venv/lib/python3.11/site-packages/telegram/request/_baserequest.py", line 197, in post
    result = await self._request_wrapper(
             ^^^^^^^^^^^^^^^^^^^^^^^^^^^^
  File "/opt/render/project/src/.venv/lib/python3.11/site-packages/telegram/request/_baserequest.py", line 355, in _request_wrapper
    raise Conflict(message)
telegram.error.Conflict: Conflict: terminated by other getUpdates request; make sure that only one bot instance is running
Deploy cancelled
2025-05-25 10:11:38,965 - httpx - INFO - HTTP Request: POST https://api.telegram.org/bot8196073831:AAFIr04r0XF0Ki2cvhH47LJGK2MMisAPk3A/getUpdates "HTTP/1.1 409 Conflict"
2025-05-25 10:11:38,966 - telegram.ext.Application - ERROR - No error handlers are registered, logging exception.
Traceback (most recent call last):
  File "/opt/render/project/src/.venv/lib/python3.11/site-packages/telegram/ext/_utils/networkloop.py", line 115, in network_retry_loop
    if not await do_action():
           ^^^^^^^^^^^^^^^^^
  File "/opt/render/project/src/.venv/lib/python3.11/site-packages/telegram/ext/_utils/networkloop.py", line 108, in do_action
    return action_cb_task.result()
           ^^^^^^^^^^^^^^^^^^^^^^^
  File "/opt/render/project/src/.venv/lib/python3.11/site-packages/telegram/ext/_updater.py", line 335, in polling_action_cb
    updates = await self.bot.get_updates(
              ^^^^^^^^^^^^^^^^^^^^^^^^^^^
  File "/opt/render/project/src/.venv/lib/python3.11/site-packages/telegram/ext/_extbot.py", line 669, in get_updates
    updates = await super().get_updates(
              ^^^^^^^^^^^^^^^^^^^^^^^^^^
  File "/opt/render/project/src/.venv/lib/python3.11/site-packages/telegram/_bot.py", line 4601, in get_updates
    await self._post(
  File "/opt/render/project/src/.venv/lib/python3.11/site-packages/telegram/_bot.py", line 697, in _post
    return await self._do_post(
           ^^^^^^^^^^^^^^^^^^^^
  File "/opt/render/project/src/.venv/lib/python3.11/site-packages/telegram/ext/_extbot.py", line 369, in _do_post
    return await super()._do_post(
           ^^^^^^^^^^^^^^^^^^^^^^^
  File "/opt/render/project/src/.venv/lib/python3.11/site-packages/telegram/_bot.py", line 726, in _do_post
    result = await request.post(
             ^^^^^^^^^^^^^^^^^^^
  File "/opt/render/project/src/.venv/lib/python3.11/site-packages/telegram/request/_baserequest.py", line 197, in post
    result = await self._request_wrapper(
             ^^^^^^^^^^^^^^^^^^^^^^^^^^^^
  File "/opt/render/project/src/.venv/lib/python3.11/site-packages/telegram/request/_baserequest.py", line 355, in _request_wrapper
    raise Conflict(message)
telegram.error.Conflict: Conflict: terminated by other getUpdates request; make sure that only one bot instance is running
Need better ways to work with logs? Try 